<?xml version="1.0"?>
<robot name="tiago_arm">
  <link name="torso_lift_link">
    </link>
  <link name="TIAGo front arm">
    <visual>
      <origin xyz="0.026 0.14 -0.232" rpy="0 0 1.5708"/>
      <geometry>
        <box size="0.042 0.094 0.094"/>
      </geometry>
    </visual>
    <collision>
      <origin xyz="0.026 0.14 -0.232" rpy="0 0 1.5708"/>
      <geometry>
        <box size="0.042 0.094 0.094"/>
      </geometry>
    </collision>
    <visual>
      <origin xyz="0.0256 0.1868 -0.2661" rpy="0.261799 0 0"/>
      <geometry>
        <cylinder radius="0.053" length="0.016"/>
      </geometry>
    </visual>
    <collision>
      <origin xyz="0.0256 0.1868 -0.2661" rpy="0.261799 0 0"/>
      <geometry>
        <cylinder radius="0.053" length="0.016"/>
      </geometry>
    </collision>
    <visual>
      <origin xyz="0.026 0.19 -0.221" rpy="0 0 -1.5708"/>
      <geometry>
        <cylinder radius="0.053" length="0.075"/>
      </geometry>
    </visual>
    <collision>
      <origin xyz="0.026 0.19 -0.221" rpy="0 0 -1.5708"/>
      <geometry>
        <cylinder radius="0.053" length="0.075"/>
      </geometry>
    </collision>
  </link>
  <joint name="torso_lift_link_TIAGo front arm_joint" type="fixed">
    <parent link="torso_lift_link"/>
    <child link="TIAGo front arm"/>
    <origin xyz="-0.037 0.0388 0.0224" rpy="0 0 -1.5708"/>
  </joint>
  <joint name="arm_1_joint" type="revolute">
    <parent link="TIAGo front arm"/>
    <child link="TIAGo front arm_3"/>
    <axis xyz="0 0 1"/>
    <limit effort="43" lower="0.07" upper="2.68" velocity="1.95"/>
    <origin xyz="0.025 0.194 -0.16" rpy="0 0 0.01"/>
  </joint>
  <link name="TIAGo front arm_3">
    <visual>
      <origin xyz="0.0001 -0.000001 0.002" rpy="0 0 1.5708"/>
      <geometry>
        <cylinder radius="0.0522" length="0.052"/>
      </geometry>
    </visual>
    <collision>
      <origin xyz="0.0001 -0.000001 0.002" rpy="0 0 1.5708"/>
      <geometry>
        <cylinder radius="0.0522" length="0.052"/>
      </geometry>
    </collision>
    <visual>
      <origin xyz="0.0331 0.000999 0.001" rpy="0 0 0"/>
      <geometry>
        <box size="0.08 0.1044 0.048"/>
      </geometry>
    </visual>
    <collision>
      <origin xyz="0.0331 0.000999 0.001" rpy="0 0 0"/>
      <geometry>
        <box size="0.08 0.1044 0.048"/>
      </geometry>
    </collision>
    <visual>
      <origin xyz="0.0721 0.028999 -0.023" rpy="0 0 0"/>
      <geometry>
        <box size="0.035 0.09 0.081"/>
      </geometry>
    </visual>
    <collision>
      <origin xyz="0.0721 0.028999 -0.023" rpy="0 0 0"/>
      <geometry>
        <box size="0.035 0.09 0.081"/>
      </geometry>
    </collision>
    <visual>
      <origin xyz="0.1251 0.052999 -0.042" rpy="1.5708 0 0"/>
      <geometry>
        <cylinder radius="0.053" length="0.069"/>
      </geometry>
    </visual>
    <collision>
      <origin xyz="0.1251 0.052999 -0.042" rpy="1.5708 0 0"/>
      <geometry>
        <cylinder radius="0.053" length="0.069"/>
      </geometry>
    </collision>
  </link>
  <joint name="arm_2_joint" type="revolute">
    <parent link="TIAGo front arm_3"/>
    <child link="arm_2_link"/>
    <axis xyz="0 0.000004 1"/>
    <limit effort="43" lower="-1.5" upper="1.02" velocity="1.95"/>
    <origin xyz="0.1251 0.019499 -0.042" rpy="1.5708 0 0"/>
  </joint>
  <link name="arm_2_link">
    <visual>
      <origin xyz="0.056 0 -0.0005" rpy="3.141593 -1.570793 3.141593"/>
      <geometry>
        <cylinder radius="0.052" length="0.048"/>
      </geometry>
    </visual>
    <collision>
      <origin xyz="0.056 0 -0.0005" rpy="3.141593 -1.570793 3.141593"/>
      <geometry>
        <cylinder radius="0.052" length="0.048"/>
      </geometry>
    </collision>
    <visual>
      <origin xyz="0 0 0.0295" rpy="0 0 -1.5708"/>
      <geometry>
        <cylinder radius="0.053" length="0.057"/>
      </geometry>
    </visual>
    <collision>
      <origin xyz="0 0 0.0295" rpy="0 0 -1.5708"/>
      <geometry>
        <cylinder radius="0.053" length="0.057"/>
      </geometry>
    </collision>
  </link>
  <joint name="arm_3_joint" type="revolute">
    <parent link="arm_2_link"/>
    <child link="arm_3_link"/>
    <axis xyz="-0.000078 -0.000095 1"/>
    <limit effort="26" lower="-3.46" upper="1.5" velocity="2.35"/>
    <origin xyz="0.0895 0 0" rpy="-1.570892 0.000095 1.570718"/>
  </joint>
  <link name="arm_3_link">
    <visual>
      <origin xyz="0 0 -0.1037" rpy="0 0 -1.5708"/>
      <geometry>
        <cylinder radius="0.053" length="0.23"/>
      </geometry>
    </visual>
    <collision>
      <origin xyz="0 0 -0.1037" rpy="0 0 -1.5708"/>
      <geometry>
        <cylinder radius="0.053" length="0.23"/>
      </geometry>
    </collision>
    <visual>
      <origin xyz="-0.0169 0.03 -0.2187" rpy="1.5708 0 0"/>
      <geometry>
        <cylinder radius="0.056" length="0.056"/>
      </geometry>
    </visual>
    <collision>
      <origin xyz="-0.0169 0.03 -0.2187" rpy="1.5708 0 0"/>
      <geometry>
        <cylinder radius="0.056" length="0.056"/>
      </geometry>
    </collision>
  </link>
  <joint name="arm_4_joint" type="revolute">
    <parent link="arm_3_link"/>
    <child link="arm_4_link"/>
    <axis xyz="0.000003 -0.000003 1"/>
    <limit effort="26" lower="-0.32" upper="2.29" velocity="2.35"/>
    <origin xyz="-0.02 -0.027 -0.2197" rpy="2.356193 -1.570792 2.356193"/>
  </joint>
  <link name="arm_4_link">
    <visual>
      <origin xyz="0 0.001 -0.002" rpy="0 0 1.5708"/>
      <geometry>
        <cylinder radius="0.054" length="0.056"/>
      </geometry>
    </visual>
    <collision>
      <origin xyz="0 0.001 -0.002" rpy="0 0 1.5708"/>
      <geometry>
        <cylinder radius="0.054" length="0.056"/>
      </geometry>
    </collision>
    <visual>
      <origin xyz="-0.093 0.019 0.027" rpy="3.141593 1.570793 3.141593"/>
      <geometry>
        <cylinder radius="0.052" length="0.191"/>
      </geometry>
    </visual>
    <collision>
      <origin xyz="-0.093 0.019 0.027" rpy="3.141593 1.570793 3.141593"/>
      <geometry>
        <cylinder radius="0.052" length="0.191"/>
      </geometry>
    </collision>
  </link>
  <joint name="arm_5_joint" type="revolute">
    <parent link="arm_4_link"/>
    <child link="arm_5_link"/>
    <axis xyz="0.000004 0 1"/>
    <limit effort="3" lower="-2.07" upper="2.07" velocity="1.95"/>
    <origin xyz="-0.162 0.02 0.027" rpy="3.141593 -1.570793 3.141593"/>
  </joint>
  <link name="arm_5_link">
    <visual>
      <origin xyz="0 0 0.04" rpy="0 0 1.57"/>
      <geometry>
        <cylinder radius="0.063" length="0.062"/>
      </geometry>
    </visual>
    <collision>
      <origin xyz="0 0 0.04" rpy="0 0 1.57"/>
      <geometry>
        <cylinder radius="0.063" length="0.062"/>
      </geometry>
    </collision>
    <visual>
      <origin xyz="0 0 0.099" rpy="0 0 1.57"/>
      <geometry>
        <cylinder radius="0.057" length="0.06"/>
      </geometry>
    </visual>
    <collision>
      <origin xyz="0 0 0.099" rpy="0 0 1.57"/>
      <geometry>
        <cylinder radius="0.057" length="0.06"/>
      </geometry>
    </collision>
    <visual>
      <origin xyz="0 0 0.156" rpy="0 0 1.57"/>
      <geometry>
        <cylinder radius="0.053" length="0.06"/>
      </geometry>
    </visual>
    <collision>
      <origin xyz="0 0 0.156" rpy="0 0 1.57"/>
      <geometry>
        <cylinder radius="0.053" length="0.06"/>
      </geometry>
    </collision>
  </link>
  <joint name="arm_6_joint" type="revolute">
    <parent link="arm_5_link"/>
    <child link="arm_6_link"/>
    <axis xyz="0.000003 -0.000003 1"/>
    <limit effort="6.6" lower="-1.39" upper="1.39" velocity="1.76"/>
    <origin xyz="0 0 0.15" rpy="2.356193 -1.570792 2.356193"/>
  </joint>
  <link name="arm_6_link">
    <visual>
      <origin xyz="0.0409 0 0" rpy="3.141593 1.570793 3.141593"/>
      <geometry>
        <cylinder radius="0.0226" length="0.013"/>
      </geometry>
    </visual>
    <collision>
      <origin xyz="0.0409 0 0" rpy="3.141593 1.570793 3.141593"/>
      <geometry>
        <cylinder radius="0.0226" length="0.013"/>
      </geometry>
    </collision>
  </link>
  <joint name="arm_7_joint" type="revolute">
    <parent link="arm_6_link"/>
    <child link="arm_7_link"/>
    <axis xyz="-0.000003 0.000003 1"/>
    <limit effort="6.6" lower="-2.07" upper="2.07" velocity="1.76"/>
    <origin xyz="0 0 0" rpy="1.570799 -0.000003 1.570799"/>
  </joint>
  <link name="arm_7_link">
    <visual>
      <origin xyz="0 0 0.055" rpy="0 0 1.5708"/>
      <geometry>
        <cylinder radius="0.0225" length="0.0157"/>
      </geometry>
    </visual>
    <collision>
      <origin xyz="0 0 0.055" rpy="0 0 1.5708"/>
      <geometry>
        <cylinder radius="0.0225" length="0.0157"/>
      </geometry>
    </collision>
  </link>
  <link name="wrist_ft_tool_link">
    <visual>
      <origin xyz="0 0 0.055" rpy="0 1.57 0"/>
      <geometry>
        <cylinder radius="0.0253" length="0.011"/>
      </geometry>
    </visual>
    <collision>
      <origin xyz="0 0 0.055" rpy="0 1.57 0"/>
      <geometry>
        <cylinder radius="0.0253" length="0.011"/>
      </geometry>
    </collision>
  </link>
  <joint name="arm_7_link_wrist_ft_tool_link_joint" type="fixed">
    <parent link="arm_7_link"/>
    <child link="wrist_ft_tool_link"/>
    <origin xyz="0 0 0.067725" rpy="2.356193 -1.570792 2.356193"/>
  </joint>
  <link name="front">
    <visual>
      <origin xyz="0 0 0" rpy="0 0 0"/>
      <geometry>
        <cylinder radius="0.0227" length="0.028"/>
      </geometry>
    </visual>
    <collision>
      <origin xyz="0 0 0" rpy="0 0 0"/>
      <geometry>
        <cylinder radius="0.0227" length="0.028"/>
      </geometry>
    </collision>
    <visual>
      <origin xyz="0.029 -0.01834 -0.046" rpy="0 0 0.59"/>
      <geometry>
        <box size="0.04 0.0217 0.105"/>
      </geometry>
    </visual>
    <collision>
      <origin xyz="0.029 -0.01834 -0.046" rpy="0 0 0.59"/>
      <geometry>
        <box size="0.04 0.0217 0.105"/>
      </geometry>
    </collision>
    <visual>
      <origin xyz="-0.029 0.01834 -0.046" rpy="0 0 0.59"/>
      <geometry>
        <box size="0.04 0.0217 0.105"/>
      </geometry>
    </visual>
    <collision>
      <origin xyz="-0.029 0.01834 -0.046" rpy="0 0 0.59"/>
      <geometry>
        <box size="0.04 0.0217 0.105"/>
      </geometry>
    </collision>
    <visual>
      <origin xyz="0.0172 0.0109 -0.046" rpy="3.141593 -1.570793 3.141593"/>
      <geometry>
        <box size="0.106 0.056 0.071"/>
      </geometry>
    </visual>
    <collision>
      <origin xyz="0.0172 0.0109 -0.046" rpy="3.141593 -1.570793 3.141593"/>
      <geometry>
        <box size="0.106 0.056 0.071"/>
      </geometry>
    </collision>
    <visual>
      <origin xyz="-0.0172 -0.0109 -0.046" rpy="3.141593 -1.570793 3.141593"/>
      <geometry>
        <box size="0.106 0.056 0.071"/>
      </geometry>
    </visual>
    <collision>
      <origin xyz="-0.0172 -0.0109 -0.046" rpy="3.141593 -1.570793 3.141593"/>
      <geometry>
        <box size="0.106 0.056 0.071"/>
      </geometry>
    </collision>
  </link>
  <joint name="wrist_ft_tool_link_front_joint" type="fixed">
    <parent link="wrist_ft_tool_link"/>
    <child link="front"/>
    <origin xyz="0 0 0.067725" rpy="2.356193 -1.570792 2.356193"/>
  </joint>
</robot>